Throwing beforehand catches the error at the source!

```
function getUserRecord (id) {
  var user = getUser(id)
  if (user[0] === 'error') throw new Error(user[1])
  /* ... */
}
```

No weird behaviour! No nasty call stacks!

But is not finding a user necessarily bad enough to crash?
